<mujoco model="bouncer">
  <compiler inertiafromgeom="true"/>
  <option timestep="0.005" gravity="0 0 -9.81"/>
  <worldbody>
    <light pos="0 0 3" dir="0 0 -1" diffuse="1 1 1"/>
        <!-- Left Wall -->
        <body name="left_wall" pos="-2 0 1"> <!-- Adjust the position as needed -->
            <geom name="left_wall_geom" type="box" size="0.1 0.1 2" rgba="0.8 0.9 0.8 1"/>
        </body>

        <!-- Right Wall -->
        <body name="right_wall" pos="2 0 1"> <!-- Adjust the position as needed -->
            <geom name="right_wall_geom" type="box" size="0.1 0.1 2" rgba="0.8 0.9 0.8 1"/>
        </body>

        <!-- Floor -->
        <body name="floor" pos="0 0 0">
            <geom name="floor_geom" type="plane" size="2 1 0.1" rgba="0.8 0.9 0.8 1"/>
        </body>

        <body name="bar" pos="0 0 1">
            <geom name="bar_geom" type="box" size="0.5 0.1 0.1" rgba="0.8 0.1 0.1 1"/>
            <joint name="bar_joint" type="slide" axis="1 0 0" range="-1 1"/>
        </body>
        <body name="ball" pos="0 0 1.5">
            <geom name="ball_geom" type="ellipsoid" size="0.17 0.11 0.11" 
                  density="100" rgba="0.1 0.1 0.8 1" solref="-1000 0"/>
            <joint name="ball_slide_x" type="slide" axis="1 0 0"/>
            <joint name="ball_slide_z" type="slide" axis="0 0 1"/>
            <joint name="ball_hinge_y" type="hinge" axis="0 1 0"/>
        </body>
    </worldbody>
    <actuator>
        <motor joint="bar_joint" ctrlrange="-5.0 5.0" ctrllimited="true"/>
    </actuator>
</mujoco>
