<mujoco model="bouncer">
  <compiler inertiafromgeom="true"/>
  <option timestep="0.005" gravity="0 0 -9.81"/>
  <worldbody>
    <light pos="0 0 3" dir="0 0 -1" diffuse="1 1 1"/>
        <body name="floor" pos="0 0 0">
            <geom name="floor_geom" type="plane" size="5 5 0.1" rgba="0.8 0.9 0.8 1"/>
        </body>
        <body name="bar" pos="0 0 1">
            <geom name="bar_geom" type="box" size="0.5 0.1 0.1" rgba="0.8 0.1 0.1 1"/>
            <joint name="bar_joint" type="slide" axis="1 0 0" range="-1 1"/>
        </body>
        <body name="ball" pos="0 0 1.5">
            <geom name="ball_geom" density="100" type="sphere" size="0.1" rgba="0.1 0.1 0.8 1" solref="-1000 0"/>
            <joint name="ball_joint" type="free"/>
        </body>
    </worldbody>
    <actuator>
        <motor joint="bar_joint" ctrlrange="-5.0 5.0" ctrllimited="true"/>
    </actuator>
</mujoco>
